2020-04-07 20:46:43 WARNING [40314-Thread-3] basehttp.log_message line 157: "GET /static/NULL HTTP/1.1" 404 1638
2020-04-07 20:47:31 WARNING [40314-Thread-8] log.log_response line 222: Not Found: /favicon.ico
2020-04-07 20:47:31 WARNING [40314-Thread-8] basehttp.log_message line 157: "GET /favicon.ico HTTP/1.1" 404 12939
2020-04-07 20:47:34 WARNING [40314-Thread-8] log.log_response line 222: Not Found: /favicon.ico
2020-04-07 20:47:34 WARNING [40314-Thread-8] basehttp.log_message line 157: "GET /favicon.ico HTTP/1.1" 404 12939
2020-04-07 20:47:35 WARNING [40314-Thread-12] log.log_response line 222: Not Found: /favicon.ico
2020-04-07 20:47:35 WARNING [40314-Thread-12] basehttp.log_message line 157: "GET /favicon.ico HTTP/1.1" 404 12939
2020-04-07 20:47:38 WARNING [40314-Thread-8] log.log_response line 222: Not Found: /favicon.ico
2020-04-07 20:47:38 WARNING [40314-Thread-8] basehttp.log_message line 157: "GET /favicon.ico HTTP/1.1" 404 12939
2020-04-07 20:47:39 WARNING [40314-Thread-8] log.log_response line 222: Not Found: /favicon.ico
2020-04-07 20:47:39 WARNING [40314-Thread-8] basehttp.log_message line 157: "GET /favicon.ico HTTP/1.1" 404 12939
2020-04-07 20:49:39 WARNING [40364-Thread-4] log.log_response line 222: Not Found: /favicon.ico
2020-04-07 20:49:39 WARNING [40364-Thread-4] basehttp.log_message line 157: "GET /favicon.ico HTTP/1.1" 404 12939
2020-04-07 20:50:33 WARNING [40373-Thread-1] basehttp.log_message line 157: "GET /static/NULL HTTP/1.1" 404 1638
2020-04-07 20:51:03 WARNING [40373-Thread-3] basehttp.log_message line 157: "GET /static/NULL HTTP/1.1" 404 1638
2020-04-07 20:58:01 ERROR [40404-Thread-1] log.log_response line 222: Internal Server Error: /
Traceback (most recent call last):
  File "/Users/xianghangxi/hellodjango/myvenv/lib/python3.8/site-packages/django_redis/cache.py", line 32, in _decorator
    return method(self, *args, **kwargs)
  File "/Users/xianghangxi/hellodjango/myvenv/lib/python3.8/site-packages/django_redis/cache.py", line 80, in get
    return self.client.get(key, default=default, version=version,
  File "/Users/xianghangxi/hellodjango/myvenv/lib/python3.8/site-packages/django_redis/client/default.py", line 201, in get
    raise ConnectionInterrupted(connection=client, parent=e)
django_redis.exceptions.ConnectionInterrupted: Redis ConnectionError: Error 61 connecting to 127.0.0.1:6379. Connection refused.

During handling of the above exception, another exception occurred:

Traceback (most recent call last):
  File "/Users/xianghangxi/hellodjango/myvenv/lib/python3.8/site-packages/django/core/handlers/exception.py", line 34, in inner
    response = get_response(request)
  File "/Users/xianghangxi/hellodjango/myvenv/lib/python3.8/site-packages/django/core/handlers/base.py", line 115, in _get_response
    response = self.process_exception_by_middleware(e, request)
  File "/Users/xianghangxi/hellodjango/myvenv/lib/python3.8/site-packages/django/core/handlers/base.py", line 113, in _get_response
    response = wrapped_callback(request, *callback_args, **callback_kwargs)
  File "/Users/xianghangxi/hellodjango/myvenv/lib/python3.8/site-packages/django/utils/decorators.py", line 122, in _wrapped_view
    result = middleware.process_request(request)
  File "/Users/xianghangxi/hellodjango/myvenv/lib/python3.8/site-packages/django/middleware/cache.py", line 137, in process_request
    cache_key = get_cache_key(request, self.key_prefix, 'GET', cache=self.cache)
  File "/Users/xianghangxi/hellodjango/myvenv/lib/python3.8/site-packages/django/utils/cache.py", line 340, in get_cache_key
    headerlist = cache.get(cache_key)
  File "/Users/xianghangxi/hellodjango/myvenv/lib/python3.8/site-packages/debug_toolbar/panels/cache.py", line 31, in wrapped
    value = method(self, *args, **kwargs)
  File "/Users/xianghangxi/hellodjango/myvenv/lib/python3.8/site-packages/debug_toolbar/panels/cache.py", line 82, in get
    return self.cache.get(*args, **kwargs)
  File "/Users/xianghangxi/hellodjango/myvenv/lib/python3.8/site-packages/django_redis/cache.py", line 39, in _decorator
    raise e.parent
  File "/Users/xianghangxi/hellodjango/myvenv/lib/python3.8/site-packages/django_redis/client/default.py", line 199, in get
    value = client.get(key)
  File "/Users/xianghangxi/hellodjango/myvenv/lib/python3.8/site-packages/redis/client.py", line 1579, in get
    return self.execute_command('GET', name)
  File "/Users/xianghangxi/hellodjango/myvenv/lib/python3.8/site-packages/redis/client.py", line 875, in execute_command
    conn = self.connection or pool.get_connection(command_name, **options)
  File "/Users/xianghangxi/hellodjango/myvenv/lib/python3.8/site-packages/redis/connection.py", line 1185, in get_connection
    connection.connect()
  File "/Users/xianghangxi/hellodjango/myvenv/lib/python3.8/site-packages/redis/connection.py", line 557, in connect
    raise ConnectionError(self._error_message(e))
redis.exceptions.ConnectionError: Error 61 connecting to 127.0.0.1:6379. Connection refused.
2020-04-07 20:58:01 ERROR [40404-Thread-1] basehttp.log_message line 157: "GET / HTTP/1.1" 500 134492
2020-04-07 21:06:44 ERROR [40425-Thread-1] log.log_response line 222: Internal Server Error: /
Traceback (most recent call last):
  File "/Users/xianghangxi/hellodjango/myvenv/lib/python3.8/site-packages/django_redis/cache.py", line 32, in _decorator
    return method(self, *args, **kwargs)
  File "/Users/xianghangxi/hellodjango/myvenv/lib/python3.8/site-packages/django_redis/cache.py", line 80, in get
    return self.client.get(key, default=default, version=version,
  File "/Users/xianghangxi/hellodjango/myvenv/lib/python3.8/site-packages/django_redis/client/default.py", line 201, in get
    raise ConnectionInterrupted(connection=client, parent=e)
django_redis.exceptions.ConnectionInterrupted: Redis ConnectionError: Error 61 connecting to 127.0.0.1:6379. Connection refused.

During handling of the above exception, another exception occurred:

Traceback (most recent call last):
  File "/Users/xianghangxi/hellodjango/myvenv/lib/python3.8/site-packages/django/core/handlers/exception.py", line 34, in inner
    response = get_response(request)
  File "/Users/xianghangxi/hellodjango/myvenv/lib/python3.8/site-packages/django/core/handlers/base.py", line 115, in _get_response
    response = self.process_exception_by_middleware(e, request)
  File "/Users/xianghangxi/hellodjango/myvenv/lib/python3.8/site-packages/django/core/handlers/base.py", line 113, in _get_response
    response = wrapped_callback(request, *callback_args, **callback_kwargs)
  File "/Users/xianghangxi/hellodjango/myvenv/lib/python3.8/site-packages/django/utils/decorators.py", line 122, in _wrapped_view
    result = middleware.process_request(request)
  File "/Users/xianghangxi/hellodjango/myvenv/lib/python3.8/site-packages/django/middleware/cache.py", line 137, in process_request
    cache_key = get_cache_key(request, self.key_prefix, 'GET', cache=self.cache)
  File "/Users/xianghangxi/hellodjango/myvenv/lib/python3.8/site-packages/django/utils/cache.py", line 340, in get_cache_key
    headerlist = cache.get(cache_key)
  File "/Users/xianghangxi/hellodjango/myvenv/lib/python3.8/site-packages/debug_toolbar/panels/cache.py", line 31, in wrapped
    value = method(self, *args, **kwargs)
  File "/Users/xianghangxi/hellodjango/myvenv/lib/python3.8/site-packages/debug_toolbar/panels/cache.py", line 82, in get
    return self.cache.get(*args, **kwargs)
  File "/Users/xianghangxi/hellodjango/myvenv/lib/python3.8/site-packages/django_redis/cache.py", line 39, in _decorator
    raise e.parent
  File "/Users/xianghangxi/hellodjango/myvenv/lib/python3.8/site-packages/django_redis/client/default.py", line 199, in get
    value = client.get(key)
  File "/Users/xianghangxi/hellodjango/myvenv/lib/python3.8/site-packages/redis/client.py", line 1579, in get
    return self.execute_command('GET', name)
  File "/Users/xianghangxi/hellodjango/myvenv/lib/python3.8/site-packages/redis/client.py", line 875, in execute_command
    conn = self.connection or pool.get_connection(command_name, **options)
  File "/Users/xianghangxi/hellodjango/myvenv/lib/python3.8/site-packages/redis/connection.py", line 1185, in get_connection
    connection.connect()
  File "/Users/xianghangxi/hellodjango/myvenv/lib/python3.8/site-packages/redis/connection.py", line 557, in connect
    raise ConnectionError(self._error_message(e))
redis.exceptions.ConnectionError: Error 61 connecting to 127.0.0.1:6379. Connection refused.
2020-04-07 21:06:44 ERROR [40425-Thread-1] basehttp.log_message line 157: "GET / HTTP/1.1" 500 133969
2020-04-07 21:06:52 ERROR [40425-Thread-1] log.log_response line 222: Internal Server Error: /
Traceback (most recent call last):
  File "/Users/xianghangxi/hellodjango/myvenv/lib/python3.8/site-packages/django/template/smartif.py", line 175, in translate_token
    op = OPERATORS[token]
KeyError: "request.session['userid']"

During handling of the above exception, another exception occurred:

Traceback (most recent call last):
  File "/Users/xianghangxi/hellodjango/myvenv/lib/python3.8/site-packages/django/core/handlers/exception.py", line 34, in inner
    response = get_response(request)
  File "/Users/xianghangxi/hellodjango/myvenv/lib/python3.8/site-packages/django/core/handlers/base.py", line 115, in _get_response
    response = self.process_exception_by_middleware(e, request)
  File "/Users/xianghangxi/hellodjango/myvenv/lib/python3.8/site-packages/django/core/handlers/base.py", line 113, in _get_response
    response = wrapped_callback(request, *callback_args, **callback_kwargs)
  File "/Users/xianghangxi/hellodjango/myvenv/lib/python3.8/site-packages/django/utils/decorators.py", line 130, in _wrapped_view
    response = view_func(request, *args, **kwargs)
  File "/Users/xianghangxi/hellodjango/vote/views.py", line 27, in show_subjects
    return render(request, 'subject.html', {'subjects': subjects})
  File "/Users/xianghangxi/hellodjango/myvenv/lib/python3.8/site-packages/django/shortcuts.py", line 19, in render
    content = loader.render_to_string(template_name, context, request, using=using)
  File "/Users/xianghangxi/hellodjango/myvenv/lib/python3.8/site-packages/django/template/loader.py", line 62, in render_to_string
    return template.render(context, request)
  File "/Users/xianghangxi/hellodjango/myvenv/lib/python3.8/site-packages/django/template/backends/django.py", line 61, in render
    return self.template.render(context)
  File "/Users/xianghangxi/hellodjango/myvenv/lib/python3.8/site-packages/django/template/base.py", line 171, in render
    return self._render(context)
  File "/Users/xianghangxi/hellodjango/myvenv/lib/python3.8/site-packages/django/test/utils.py", line 95, in instrumented_test_render
    return self.nodelist.render(context)
  File "/Users/xianghangxi/hellodjango/myvenv/lib/python3.8/site-packages/django/template/base.py", line 936, in render
    bit = node.render_annotated(context)
  File "/Users/xianghangxi/hellodjango/myvenv/lib/python3.8/site-packages/django/template/base.py", line 903, in render_annotated
    return self.render(context)
  File "/Users/xianghangxi/hellodjango/myvenv/lib/python3.8/site-packages/django/template/loader_tags.py", line 176, in render
    template = context.template.engine.get_template(template_name)
  File "/Users/xianghangxi/hellodjango/myvenv/lib/python3.8/site-packages/django/template/engine.py", line 143, in get_template
    template, origin = self.find_template(template_name)
  File "/Users/xianghangxi/hellodjango/myvenv/lib/python3.8/site-packages/django/template/engine.py", line 125, in find_template
    template = loader.get_template(name, skip=skip)
  File "/Users/xianghangxi/hellodjango/myvenv/lib/python3.8/site-packages/django/template/loaders/base.py", line 29, in get_template
    return Template(
  File "/Users/xianghangxi/hellodjango/myvenv/lib/python3.8/site-packages/django/template/base.py", line 156, in __init__
    self.nodelist = self.compile_nodelist()
  File "/Users/xianghangxi/hellodjango/myvenv/lib/python3.8/site-packages/django/template/base.py", line 194, in compile_nodelist
    return parser.parse()
  File "/Users/xianghangxi/hellodjango/myvenv/lib/python3.8/site-packages/django/template/base.py", line 477, in parse
    raise self.error(token, e)
  File "/Users/xianghangxi/hellodjango/myvenv/lib/python3.8/site-packages/django/template/base.py", line 475, in parse
    compiled_result = compile_func(self, token)
  File "/Users/xianghangxi/hellodjango/myvenv/lib/python3.8/site-packages/django/template/defaulttags.py", line 951, in do_if
    condition = TemplateIfParser(parser, bits).parse()
  File "/Users/xianghangxi/hellodjango/myvenv/lib/python3.8/site-packages/django/template/defaulttags.py", line 884, in __init__
    super().__init__(*args, **kwargs)
  File "/Users/xianghangxi/hellodjango/myvenv/lib/python3.8/site-packages/django/template/smartif.py", line 166, in __init__
    mapped_tokens.append(self.translate_token(token))
  File "/Users/xianghangxi/hellodjango/myvenv/lib/python3.8/site-packages/django/template/smartif.py", line 177, in translate_token
    return self.create_var(token)
  File "/Users/xianghangxi/hellodjango/myvenv/lib/python3.8/site-packages/django/template/defaulttags.py", line 887, in create_var
    return TemplateLiteral(self.template_parser.compile_filter(value), value)
  File "/Users/xianghangxi/hellodjango/myvenv/lib/python3.8/site-packages/django/template/base.py", line 562, in compile_filter
    return FilterExpression(token, self)
  File "/Users/xianghangxi/hellodjango/myvenv/lib/python3.8/site-packages/django/template/base.py", line 661, in __init__
    raise TemplateSyntaxError("Could not parse the remainder: '%s' "
django.template.exceptions.TemplateSyntaxError: Could not parse the remainder: '['userid']' from 'request.session['userid']'
2020-04-07 21:06:52 ERROR [40425-Thread-1] basehttp.log_message line 157: "GET / HTTP/1.1" 500 185568
2020-04-07 21:19:18 WARNING [40494-Thread-1] basehttp.log_message line 157: "GET /static/NULL HTTP/1.1" 404 1638
2020-04-07 21:19:24 WARNING [40494-Thread-5] basehttp.log_message line 157: "GET /static/NULL HTTP/1.1" 404 1638
2020-04-07 21:19:30 WARNING [40494-Thread-6] basehttp.log_message line 157: "GET /static/NULL HTTP/1.1" 404 1638
2020-04-07 21:19:35 WARNING [40494-Thread-7] basehttp.log_message line 157: "GET /static/NULL HTTP/1.1" 404 1638
2020-04-07 21:33:15 WARNING [40534-Thread-1] basehttp.log_message line 157: "GET /static/NULL HTTP/1.1" 404 1638
2020-04-07 21:33:22 WARNING [40534-Thread-7] basehttp.log_message line 157: "GET /static/NULL HTTP/1.1" 404 1638
2020-04-07 21:34:13 WARNING [40534-Thread-9] basehttp.log_message line 157: "GET /static/NULL HTTP/1.1" 404 1638
2020-04-07 21:34:49 WARNING [40534-Thread-16] basehttp.log_message line 157: "GET /static/NULL HTTP/1.1" 404 1638
2020-04-07 21:34:53 WARNING [40534-Thread-18] basehttp.log_message line 157: "GET /static/NULL HTTP/1.1" 404 1638
2020-04-07 21:34:57 WARNING [40534-Thread-19] basehttp.log_message line 157: "GET /static/NULL HTTP/1.1" 404 1638
2020-04-07 21:35:00 WARNING [40534-Thread-20] basehttp.log_message line 157: "GET /static/NULL HTTP/1.1" 404 1638
2020-04-07 21:36:14 WARNING [40534-Thread-27] log.log_response line 222: Not Found: /favicon.ico
2020-04-07 21:36:14 WARNING [40534-Thread-27] basehttp.log_message line 157: "GET /favicon.ico HTTP/1.1" 404 12939
2020-04-07 21:36:54 WARNING [40534-Thread-27] basehttp.log_message line 157: "GET /static/NULL HTTP/1.1" 404 1638
2020-04-08 12:31:28 ERROR [41260-Thread-1] log.log_response line 222: Internal Server Error: /
Traceback (most recent call last):
  File "/Users/xianghangxi/hellodjango/myvenv/lib/python3.8/site-packages/django_redis/cache.py", line 32, in _decorator
    return method(self, *args, **kwargs)
  File "/Users/xianghangxi/hellodjango/myvenv/lib/python3.8/site-packages/django_redis/cache.py", line 80, in get
    return self.client.get(key, default=default, version=version,
  File "/Users/xianghangxi/hellodjango/myvenv/lib/python3.8/site-packages/django_redis/client/default.py", line 201, in get
    raise ConnectionInterrupted(connection=client, parent=e)
django_redis.exceptions.ConnectionInterrupted: Redis ConnectionError: Error 61 connecting to 127.0.0.1:6379. Connection refused.

During handling of the above exception, another exception occurred:

Traceback (most recent call last):
  File "/Users/xianghangxi/hellodjango/myvenv/lib/python3.8/site-packages/django/core/handlers/exception.py", line 34, in inner
    response = get_response(request)
  File "/Users/xianghangxi/hellodjango/myvenv/lib/python3.8/site-packages/django/core/handlers/base.py", line 115, in _get_response
    response = self.process_exception_by_middleware(e, request)
  File "/Users/xianghangxi/hellodjango/myvenv/lib/python3.8/site-packages/django/core/handlers/base.py", line 113, in _get_response
    response = wrapped_callback(request, *callback_args, **callback_kwargs)
  File "/Users/xianghangxi/hellodjango/myvenv/lib/python3.8/site-packages/django/utils/decorators.py", line 122, in _wrapped_view
    result = middleware.process_request(request)
  File "/Users/xianghangxi/hellodjango/myvenv/lib/python3.8/site-packages/django/middleware/cache.py", line 137, in process_request
    cache_key = get_cache_key(request, self.key_prefix, 'GET', cache=self.cache)
  File "/Users/xianghangxi/hellodjango/myvenv/lib/python3.8/site-packages/django/utils/cache.py", line 340, in get_cache_key
    headerlist = cache.get(cache_key)
  File "/Users/xianghangxi/hellodjango/myvenv/lib/python3.8/site-packages/debug_toolbar/panels/cache.py", line 31, in wrapped
    value = method(self, *args, **kwargs)
  File "/Users/xianghangxi/hellodjango/myvenv/lib/python3.8/site-packages/debug_toolbar/panels/cache.py", line 82, in get
    return self.cache.get(*args, **kwargs)
  File "/Users/xianghangxi/hellodjango/myvenv/lib/python3.8/site-packages/django_redis/cache.py", line 39, in _decorator
    raise e.parent
  File "/Users/xianghangxi/hellodjango/myvenv/lib/python3.8/site-packages/django_redis/client/default.py", line 199, in get
    value = client.get(key)
  File "/Users/xianghangxi/hellodjango/myvenv/lib/python3.8/site-packages/redis/client.py", line 1579, in get
    return self.execute_command('GET', name)
  File "/Users/xianghangxi/hellodjango/myvenv/lib/python3.8/site-packages/redis/client.py", line 875, in execute_command
    conn = self.connection or pool.get_connection(command_name, **options)
  File "/Users/xianghangxi/hellodjango/myvenv/lib/python3.8/site-packages/redis/connection.py", line 1185, in get_connection
    connection.connect()
  File "/Users/xianghangxi/hellodjango/myvenv/lib/python3.8/site-packages/redis/connection.py", line 557, in connect
    raise ConnectionError(self._error_message(e))
redis.exceptions.ConnectionError: Error 61 connecting to 127.0.0.1:6379. Connection refused.
2020-04-08 12:31:28 ERROR [41260-Thread-1] basehttp.log_message line 157: "GET / HTTP/1.1" 500 134188
2020-04-08 12:39:47 ERROR [41344-Thread-1] log.log_response line 222: Internal Server Error: /
Traceback (most recent call last):
  File "/Users/xianghangxi/hellodjango/myvenv/lib/python3.8/site-packages/django/core/handlers/exception.py", line 34, in inner
    response = get_response(request)
  File "/Users/xianghangxi/hellodjango/myvenv/lib/python3.8/site-packages/django/core/handlers/base.py", line 115, in _get_response
    response = self.process_exception_by_middleware(e, request)
  File "/Users/xianghangxi/hellodjango/myvenv/lib/python3.8/site-packages/django/core/handlers/base.py", line 113, in _get_response
    response = wrapped_callback(request, *callback_args, **callback_kwargs)
  File "/Users/xianghangxi/hellodjango/myvenv/lib/python3.8/site-packages/django/utils/decorators.py", line 130, in _wrapped_view
    response = view_func(request, *args, **kwargs)
  File "/Users/xianghangxi/hellodjango/myvenv/lib/python3.8/site-packages/django/views/decorators/vary.py", line 38, in inner_func
    response = func(*args, **kwargs)
  File "/Users/xianghangxi/hellodjango/vote/views.py", line 27, in show_subjects
    return render(request, '../static/front_end/subject.html', {'subjects': subjects})
  File "/Users/xianghangxi/hellodjango/myvenv/lib/python3.8/site-packages/django/shortcuts.py", line 19, in render
    content = loader.render_to_string(template_name, context, request, using=using)
  File "/Users/xianghangxi/hellodjango/myvenv/lib/python3.8/site-packages/django/template/loader.py", line 61, in render_to_string
    template = get_template(template_name, using=using)
  File "/Users/xianghangxi/hellodjango/myvenv/lib/python3.8/site-packages/django/template/loader.py", line 19, in get_template
    raise TemplateDoesNotExist(template_name, chain=chain)
django.template.exceptions.TemplateDoesNotExist: ../static/front_end/subject.html
2020-04-08 12:39:47 ERROR [41344-Thread-1] basehttp.log_message line 157: "GET / HTTP/1.1" 500 99933
